<robot name = "robot">
    <link name="Torso1">
        <inertial>
            <origin xyz="0 0.33248114039502324 0" rpy="0 0 0"/>
            <mass value="1" />
            <inertia ixx="100" ixy="0" ixz="0" iyy="100" iyz="0" izz="100" />
        </inertial>
        <visual>
            <origin xyz="0 0.33248114039502324 0" rpy="0 0 0"/>
            <geometry>
                <box size="0.2924475531447507 0.6649622807900465 0.952278840755999" />
            </geometry>
            <material name="Green">
                <color rgba="0 1.2 0 1.0"/>
            </material>
        </visual>
        <collision>
            <origin xyz="0 0.33248114039502324 0" rpy="0 0 0"/>
            <geometry>
                <box size="0.2924475531447507 0.6649622807900465 0.952278840755999" />
            </geometry>
        </collision>
    </link>
    <link name="Torso2">
        <inertial>
            <origin xyz="0.2332561173676873 0 0" rpy="0 0 0"/>
            <mass value="1" />
            <inertia ixx="100" ixy="0" ixz="0" iyy="100" iyz="0" izz="100" />
        </inertial>
        <visual>
            <origin xyz="0.2332561173676873 0 0" rpy="0 0 0"/>
            <geometry>
                <box size="0.4665122347353746 0.526150155365436 0.6938396056281617" />
            </geometry>
            <material name="Green">
                <color rgba="0 1.2 0 1.0"/>
            </material>
        </visual>
        <collision>
            <origin xyz="0.2332561173676873 0 0" rpy="0 0 0"/>
            <geometry>
                <box size="0.4665122347353746 0.526150155365436 0.6938396056281617" />
            </geometry>
        </collision>
    </link>
    <link name="Torso3">
        <inertial>
            <origin xyz="0 0 0.2606569511329413" rpy="0 0 0"/>
            <mass value="1" />
            <inertia ixx="100" ixy="0" ixz="0" iyy="100" iyz="0" izz="100" />
        </inertial>
        <visual>
            <origin xyz="0 0 0.2606569511329413" rpy="0 0 0"/>
            <geometry>
                <box size="0.3759739922076179 0.6317831267863729 0.5213139022658826" />
            </geometry>
            <material name="Green">
                <color rgba="0 1.2 0 1.0"/>
            </material>
        </visual>
        <collision>
            <origin xyz="0 0 0.2606569511329413" rpy="0 0 0"/>
            <geometry>
                <box size="0.3759739922076179 0.6317831267863729 0.5213139022658826" />
            </geometry>
        </collision>
    </link>
    <link name="Torso4">
        <inertial>
            <origin xyz="0.46384930246548617 0 0" rpy="0 0 0"/>
            <mass value="1" />
            <inertia ixx="100" ixy="0" ixz="0" iyy="100" iyz="0" izz="100" />
        </inertial>
        <visual>
            <origin xyz="0.46384930246548617 0 0" rpy="0 0 0"/>
            <geometry>
                <box size="0.9276986049309723 0.7587466254676687 0.4096115700056472" />
            </geometry>
            <material name="Blue">
                <color rgba="0 0 2.5 1.0"/>
            </material>
        </visual>
        <collision>
            <origin xyz="0.46384930246548617 0 0" rpy="0 0 0"/>
            <geometry>
                <box size="0.9276986049309723 0.7587466254676687 0.4096115700056472" />
            </geometry>
        </collision>
    </link>
    <link name="Torso5">
        <inertial>
            <origin xyz="0 0 0.35236248723105323" rpy="0 0 0"/>
            <mass value="1" />
            <inertia ixx="100" ixy="0" ixz="0" iyy="100" iyz="0" izz="100" />
        </inertial>
        <visual>
            <origin xyz="0 0 0.35236248723105323" rpy="0 0 0"/>
            <geometry>
                <box size="0.790836107560984 0.8552240746934092 0.7047249744621065" />
            </geometry>
            <material name="Blue">
                <color rgba="0 0 2.5 1.0"/>
            </material>
        </visual>
        <collision>
            <origin xyz="0 0 0.35236248723105323" rpy="0 0 0"/>
            <geometry>
                <box size="0.790836107560984 0.8552240746934092 0.7047249744621065" />
            </geometry>
        </collision>
    </link>
    <joint name="Torso1_Torso2" type="revolute">
       <parent link="Torso1"/>
       <child  link="Torso2"/>
       <origin rpy="0 0 0" xyz="0.14622377657237534 0.33248114039502324 0" />
       <axis xyz="0 1 0"/>
       <limit effort="0.0" lower="-3.14159" upper="3.14159" velocity="0.0"/>
    </joint>
    <joint name="Torso2_Torso3" type="revolute">
       <parent link="Torso2"/>
       <child  link="Torso3"/>
       <origin rpy="0 0 0" xyz="0.2332561173676873 0 0.34691980281408086" />
       <axis xyz="0 1 0"/>
       <limit effort="0.0" lower="-3.14159" upper="3.14159" velocity="0.0"/>
    </joint>
    <joint name="Torso3_Torso4" type="revolute">
       <parent link="Torso3"/>
       <child  link="Torso4"/>
       <origin rpy="0 0 0" xyz="0.18798699610380895 0 0.2606569511329413" />
       <axis xyz="1 0 0"/>
       <limit effort="0.0" lower="-3.14159" upper="3.14159" velocity="0.0"/>
    </joint>
    <joint name="Torso4_Torso5" type="revolute">
       <parent link="Torso4"/>
       <child  link="Torso5"/>
       <origin rpy="0 0 0" xyz="0.46384930246548617 0 0.2048057850028236" />
       <axis xyz="1 0 0"/>
       <limit effort="0.0" lower="-3.14159" upper="3.14159" velocity="0.0"/>
    </joint>
</robot>