<robot name = "robot">
    <link name="Torso1">
        <inertial>
            <origin xyz="0 0 2" rpy="0 0 0"/>
            <mass value="1" />
            <inertia ixx="100" ixy="0" ixz="0" iyy="100" iyz="0" izz="100" />
        </inertial>
        <visual>
            <origin xyz="0 0 2" rpy="0 0 0"/>
            <geometry>
                <box size="0.09360974642781572 0.6697014306381986 0.15012744005170564" />
            </geometry>
            <material name="Green">
                <color rgba="0 1.2 0 1.0"/>
            </material>
        </visual>
        <collision>
            <origin xyz="0 0 2" rpy="0 0 0"/>
            <geometry>
                <box size="0.09360974642781572 0.6697014306381986 0.15012744005170564" />
            </geometry>
        </collision>
    </link>
    <joint name="Torso1_Torso2" type="revolute">
       <parent link="Torso1"/>
       <child  link="Torso2"/>
       <origin rpy="0 0 0" xyz="0.04680487321390786 0 2" />
       <axis xyz="0 1 0"/>
       <limit effort="0.0" lower="-3.14159" upper="3.14159" velocity="0.0"/>
    </joint>
    <link name="Torso2">
        <inertial>
            <origin xyz="0.13378683163668614 0 0" rpy="0 0 0"/>
            <mass value="1" />
            <inertia ixx="100" ixy="0" ixz="0" iyy="100" iyz="0" izz="100" />
        </inertial>
        <visual>
            <origin xyz="0.13378683163668614 0 0" rpy="0 0 0"/>
            <geometry>
                <box size="0.2675736632733723 0.8170870459537963 0.6080286473243297" />
            </geometry>
            <material name="Blue">
                <color rgba="0 0 2.5 1.0"/>
            </material>
        </visual>
        <collision>
            <origin xyz="0.13378683163668614 0 0" rpy="0 0 0"/>
            <geometry>
                <box size="0.2675736632733723 0.8170870459537963 0.6080286473243297" />
            </geometry>
        </collision>
    </link>
</robot>