<robot name = "robot">
    <link name="Torso1">
        <inertial>
            <origin xyz="0 0 3" rpy="0 0 0"/>
            <mass value="1" />
            <inertia ixx="100" ixy="0" ixz="0" iyy="100" iyz="0" izz="100" />
        </inertial>
        <visual>
            <origin xyz="0 0 3" rpy="0 0 0"/>
            <geometry>
                <box size="0.8120906944912345 0.35010568889953053 0.4785435973101613" />
            </geometry>
            <material name="Blue">
                <color rgba="0 0 2.55 1.0"/>
            </material>
        </visual>
        <collision>
            <origin xyz="0 0 3" rpy="0 0 0"/>
            <geometry>
                <box size="0.8120906944912345 0.35010568889953053 0.4785435973101613" />
            </geometry>
        </collision>
    </link>
    <joint name="Torso1_Torso2" type="revolute">
       <parent link="Torso1"/>
       <child  link="Torso2"/>
       <origin rpy="0 0 0" xyz="0.40604534724561725 0 3" />
       <axis xyz="0 1 0"/>
       <limit effort="0.0" lower="-3.14159" upper="3.14159" velocity="0.0"/>
    </joint>
    <link name="Torso2">
        <inertial>
            <origin xyz="0.47313725648232247 0 0" rpy="0 0 0"/>
            <mass value="1" />
            <inertia ixx="100" ixy="0" ixz="0" iyy="100" iyz="0" izz="100" />
        </inertial>
        <visual>
            <origin xyz="0.47313725648232247 0 0" rpy="0 0 0"/>
            <geometry>
                <box size="0.9462745129646449 0.28251851796759564 0.3903095950873555" />
            </geometry>
            <material name="Green">
                <color rgba="0 1.28 0 1.0"/>
            </material>
        </visual>
        <collision>
            <origin xyz="0.47313725648232247 0 0" rpy="0 0 0"/>
            <geometry>
                <box size="0.9462745129646449 0.28251851796759564 0.3903095950873555" />
            </geometry>
        </collision>
    </link>
    <joint name="Torso2_Torso3" type="revolute">
       <parent link="Torso2"/>
       <child  link="Torso3"/>
       <origin rpy="0 0 0" xyz="0.9462745129646449 0 0" />
       <axis xyz="0 1 0"/>
       <limit effort="0.0" lower="-3.14159" upper="3.14159" velocity="0.0"/>
    </joint>
    <link name="Torso3">
        <inertial>
            <origin xyz="0.03761593122125678 0 0" rpy="0 0 0"/>
            <mass value="1" />
            <inertia ixx="100" ixy="0" ixz="0" iyy="100" iyz="0" izz="100" />
        </inertial>
        <visual>
            <origin xyz="0.03761593122125678 0 0" rpy="0 0 0"/>
            <geometry>
                <box size="0.07523186244251356 0.15153419753810482 0.5670925991490906" />
            </geometry>
            <material name="Blue">
                <color rgba="0 0 2.55 1.0"/>
            </material>
        </visual>
        <collision>
            <origin xyz="0.03761593122125678 0 0" rpy="0 0 0"/>
            <geometry>
                <box size="0.07523186244251356 0.15153419753810482 0.5670925991490906" />
            </geometry>
        </collision>
    </link>
    <joint name="Torso3_Torso4" type="revolute">
       <parent link="Torso3"/>
       <child  link="Torso4"/>
       <origin rpy="0 0 0" xyz="0.07523186244251356 0 0" />
       <axis xyz="0 1 0"/>
       <limit effort="0.0" lower="-3.14159" upper="3.14159" velocity="0.0"/>
    </joint>
    <link name="Torso4">
        <inertial>
            <origin xyz="0.11606358983577097 0 0" rpy="0 0 0"/>
            <mass value="1" />
            <inertia ixx="100" ixy="0" ixz="0" iyy="100" iyz="0" izz="100" />
        </inertial>
        <visual>
            <origin xyz="0.11606358983577097 0 0" rpy="0 0 0"/>
            <geometry>
                <box size="0.23212717967154195 0.06906175693854433 0.6984504197447119" />
            </geometry>
            <material name="Green">
                <color rgba="0 1.28 0 1.0"/>
            </material>
        </visual>
        <collision>
            <origin xyz="0.11606358983577097 0 0" rpy="0 0 0"/>
            <geometry>
                <box size="0.23212717967154195 0.06906175693854433 0.6984504197447119" />
            </geometry>
        </collision>
    </link>
    <joint name="Torso4_Torso5" type="revolute">
       <parent link="Torso4"/>
       <child  link="Torso5"/>
       <origin rpy="0 0 0" xyz="0.23212717967154195 0 0" />
       <axis xyz="0 1 0"/>
       <limit effort="0.0" lower="-3.14159" upper="3.14159" velocity="0.0"/>
    </joint>
    <link name="Torso5">
        <inertial>
            <origin xyz="0.0667015838395204 0 0" rpy="0 0 0"/>
            <mass value="1" />
            <inertia ixx="100" ixy="0" ixz="0" iyy="100" iyz="0" izz="100" />
        </inertial>
        <visual>
            <origin xyz="0.0667015838395204 0 0" rpy="0 0 0"/>
            <geometry>
                <box size="0.1334031676790408 0.9144861625037822 0.2705282937929485" />
            </geometry>
            <material name="Green">
                <color rgba="0 1.28 0 1.0"/>
            </material>
        </visual>
        <collision>
            <origin xyz="0.0667015838395204 0 0" rpy="0 0 0"/>
            <geometry>
                <box size="0.1334031676790408 0.9144861625037822 0.2705282937929485" />
            </geometry>
        </collision>
    </link>
    <joint name="Torso5_Torso6" type="revolute">
       <parent link="Torso5"/>
       <child  link="Torso6"/>
       <origin rpy="0 0 0" xyz="0.1334031676790408 0 0" />
       <axis xyz="0 1 0"/>
       <limit effort="0.0" lower="-3.14159" upper="3.14159" velocity="0.0"/>
    </joint>
    <link name="Torso6">
        <inertial>
            <origin xyz="0.13576751454436975 0 0" rpy="0 0 0"/>
            <mass value="1" />
            <inertia ixx="100" ixy="0" ixz="0" iyy="100" iyz="0" izz="100" />
        </inertial>
        <visual>
            <origin xyz="0.13576751454436975 0 0" rpy="0 0 0"/>
            <geometry>
                <box size="0.2715350290887395 0.6301709185730674 0.6614290641003125" />
            </geometry>
            <material name="Blue">
                <color rgba="0 0 2.55 1.0"/>
            </material>
        </visual>
        <collision>
            <origin xyz="0.13576751454436975 0 0" rpy="0 0 0"/>
            <geometry>
                <box size="0.2715350290887395 0.6301709185730674 0.6614290641003125" />
            </geometry>
        </collision>
    </link>
    <joint name="Torso6_Torso7" type="revolute">
       <parent link="Torso6"/>
       <child  link="Torso7"/>
       <origin rpy="0 0 0" xyz="0.2715350290887395 0 0" />
       <axis xyz="0 1 0"/>
       <limit effort="0.0" lower="-3.14159" upper="3.14159" velocity="0.0"/>
    </joint>
    <link name="Torso7">
        <inertial>
            <origin xyz="0.19313964264188332 0 0" rpy="0 0 0"/>
            <mass value="1" />
            <inertia ixx="100" ixy="0" ixz="0" iyy="100" iyz="0" izz="100" />
        </inertial>
        <visual>
            <origin xyz="0.19313964264188332 0 0" rpy="0 0 0"/>
            <geometry>
                <box size="0.38627928528376665 0.356955352087743 0.21497833211072048" />
            </geometry>
            <material name="Green">
                <color rgba="0 1.28 0 1.0"/>
            </material>
        </visual>
        <collision>
            <origin xyz="0.19313964264188332 0 0" rpy="0 0 0"/>
            <geometry>
                <box size="0.38627928528376665 0.356955352087743 0.21497833211072048" />
            </geometry>
        </collision>
    </link>
    <joint name="Torso7_Torso8" type="revolute">
       <parent link="Torso7"/>
       <child  link="Torso8"/>
       <origin rpy="0 0 0" xyz="0.38627928528376665 0 0" />
       <axis xyz="0 1 0"/>
       <limit effort="0.0" lower="-3.14159" upper="3.14159" velocity="0.0"/>
    </joint>
    <link name="Torso8">
        <inertial>
            <origin xyz="0.30465757901139334 0 0" rpy="0 0 0"/>
            <mass value="1" />
            <inertia ixx="100" ixy="0" ixz="0" iyy="100" iyz="0" izz="100" />
        </inertial>
        <visual>
            <origin xyz="0.30465757901139334 0 0" rpy="0 0 0"/>
            <geometry>
                <box size="0.6093151580227867 0.11743816471765045 0.7234943856587951" />
            </geometry>
            <material name="Blue">
                <color rgba="0 0 2.55 1.0"/>
            </material>
        </visual>
        <collision>
            <origin xyz="0.30465757901139334 0 0" rpy="0 0 0"/>
            <geometry>
                <box size="0.6093151580227867 0.11743816471765045 0.7234943856587951" />
            </geometry>
        </collision>
    </link>
    <joint name="Torso8_Torso9" type="revolute">
       <parent link="Torso8"/>
       <child  link="Torso9"/>
       <origin rpy="0 0 0" xyz="0.6093151580227867 0 0" />
       <axis xyz="0 1 0"/>
       <limit effort="0.0" lower="-3.14159" upper="3.14159" velocity="0.0"/>
    </joint>
    <link name="Torso9">
        <inertial>
            <origin xyz="0.01163720119885997 0 0" rpy="0 0 0"/>
            <mass value="1" />
            <inertia ixx="100" ixy="0" ixz="0" iyy="100" iyz="0" izz="100" />
        </inertial>
        <visual>
            <origin xyz="0.01163720119885997 0 0" rpy="0 0 0"/>
            <geometry>
                <box size="0.02327440239771994 0.0812156421512702 0.8625370461338405" />
            </geometry>
            <material name="Green">
                <color rgba="0 1.28 0 1.0"/>
            </material>
        </visual>
        <collision>
            <origin xyz="0.01163720119885997 0 0" rpy="0 0 0"/>
            <geometry>
                <box size="0.02327440239771994 0.0812156421512702 0.8625370461338405" />
            </geometry>
        </collision>
    </link>
    <joint name="Torso9_Torso10" type="revolute">
       <parent link="Torso9"/>
       <child  link="Torso10"/>
       <origin rpy="0 0 0" xyz="0.02327440239771994 0 0" />
       <axis xyz="0 1 0"/>
       <limit effort="0.0" lower="-3.14159" upper="3.14159" velocity="0.0"/>
    </joint>
    <link name="Torso10">
        <inertial>
            <origin xyz="0.4324653278220588 0 0" rpy="0 0 0"/>
            <mass value="1" />
            <inertia ixx="100" ixy="0" ixz="0" iyy="100" iyz="0" izz="100" />
        </inertial>
        <visual>
            <origin xyz="0.4324653278220588 0 0" rpy="0 0 0"/>
            <geometry>
                <box size="0.8649306556441176 0.9084130209439196 0.8746887639746598" />
            </geometry>
            <material name="Blue">
                <color rgba="0 0 2.55 1.0"/>
            </material>
        </visual>
        <collision>
            <origin xyz="0.4324653278220588 0 0" rpy="0 0 0"/>
            <geometry>
                <box size="0.8649306556441176 0.9084130209439196 0.8746887639746598" />
            </geometry>
        </collision>
    </link>
</robot>