<robot name = "robot">
    <link name="Torso1">
        <inertial>
            <origin xyz="0 0 3" rpy="0 0 0"/>
            <mass value="1" />
            <inertia ixx="100" ixy="0" ixz="0" iyy="100" iyz="0" izz="100" />
        </inertial>
        <visual>
            <origin xyz="0 0 3" rpy="0 0 0"/>
            <geometry>
                <box size="0.1508909230678307 0.20798078580769497 0.8484272564035092" />
            </geometry>
            <material name="Green">
                <color rgba="0 1.28 0 1.0"/>
            </material>
        </visual>
        <collision>
            <origin xyz="0 0 3" rpy="0 0 0"/>
            <geometry>
                <box size="0.1508909230678307 0.20798078580769497 0.8484272564035092" />
            </geometry>
        </collision>
    </link>
    <joint name="Torso1_Torso2" type="revolute">
       <parent link="Torso1"/>
       <child  link="Torso2"/>
       <origin rpy="0 0 0" xyz="0.07544546153391535 0 3" />
       <axis xyz="0 1 0"/>
       <limit effort="0.0" lower="-3.14159" upper="3.14159" velocity="0.0"/>
    </joint>
    <link name="Torso2">
        <inertial>
            <origin xyz="0.14363430547807637 0 0" rpy="0 0 0"/>
            <mass value="1" />
            <inertia ixx="100" ixy="0" ixz="0" iyy="100" iyz="0" izz="100" />
        </inertial>
        <visual>
            <origin xyz="0.14363430547807637 0 0" rpy="0 0 0"/>
            <geometry>
                <box size="0.28726861095615275 0.43229124969720545 0.8722880486512228" />
            </geometry>
            <material name="Blue">
                <color rgba="0 0 2.55 1.0"/>
            </material>
        </visual>
        <collision>
            <origin xyz="0.14363430547807637 0 0" rpy="0 0 0"/>
            <geometry>
                <box size="0.28726861095615275 0.43229124969720545 0.8722880486512228" />
            </geometry>
        </collision>
    </link>
    <joint name="Torso02_Torso3" type="revolute">
       <parent link="Torso2"/>
       <child  link="Torso3"/>
       <origin rpy="0 0 0" xyz="0.28726861095615275 0 0" />
       <axis xyz="0 1 0"/>
       <limit effort="0.0" lower="-3.14159" upper="3.14159" velocity="0.0"/>
    </joint>
    <link name="Torso3">
        <inertial>
            <origin xyz="0.40686392856397874 0 0" rpy="0 0 0"/>
            <mass value="1" />
            <inertia ixx="100" ixy="0" ixz="0" iyy="100" iyz="0" izz="100" />
        </inertial>
        <visual>
            <origin xyz="0.40686392856397874 0 0" rpy="0 0 0"/>
            <geometry>
                <box size="0.8137278571279575 0.8838178291021835 0.8683323603899004" />
            </geometry>
            <material name="Green">
                <color rgba="0 1.28 0 1.0"/>
            </material>
        </visual>
        <collision>
            <origin xyz="0.40686392856397874 0 0" rpy="0 0 0"/>
            <geometry>
                <box size="0.8137278571279575 0.8838178291021835 0.8683323603899004" />
            </geometry>
        </collision>
    </link>
    <joint name="Torso03_Torso4" type="revolute">
       <parent link="Torso3"/>
       <child  link="Torso4"/>
       <origin rpy="0 0 0" xyz="0.8137278571279575 0 0" />
       <axis xyz="0 1 0"/>
       <limit effort="0.0" lower="-3.14159" upper="3.14159" velocity="0.0"/>
    </joint>
    <link name="Torso4">
        <inertial>
            <origin xyz="0.2449684050362299 0 0" rpy="0 0 0"/>
            <mass value="1" />
            <inertia ixx="100" ixy="0" ixz="0" iyy="100" iyz="0" izz="100" />
        </inertial>
        <visual>
            <origin xyz="0.2449684050362299 0 0" rpy="0 0 0"/>
            <geometry>
                <box size="0.4899368100724598 0.45400185859945885 0.6132641790587987" />
            </geometry>
            <material name="Green">
                <color rgba="0 1.28 0 1.0"/>
            </material>
        </visual>
        <collision>
            <origin xyz="0.2449684050362299 0 0" rpy="0 0 0"/>
            <geometry>
                <box size="0.4899368100724598 0.45400185859945885 0.6132641790587987" />
            </geometry>
        </collision>
    </link>
    <joint name="Torso04_Torso5" type="revolute">
       <parent link="Torso4"/>
       <child  link="Torso5"/>
       <origin rpy="0 0 0" xyz="0.4899368100724598 0 0" />
       <axis xyz="0 1 0"/>
       <limit effort="0.0" lower="-3.14159" upper="3.14159" velocity="0.0"/>
    </joint>
    <link name="Torso5">
        <inertial>
            <origin xyz="0.36136693535603437 0 0" rpy="0 0 0"/>
            <mass value="1" />
            <inertia ixx="100" ixy="0" ixz="0" iyy="100" iyz="0" izz="100" />
        </inertial>
        <visual>
            <origin xyz="0.36136693535603437 0 0" rpy="0 0 0"/>
            <geometry>
                <box size="0.7227338707120687 0.010167537454707887 0.9043427595181945" />
            </geometry>
            <material name="Blue">
                <color rgba="0 0 2.55 1.0"/>
            </material>
        </visual>
        <collision>
            <origin xyz="0.36136693535603437 0 0" rpy="0 0 0"/>
            <geometry>
                <box size="0.7227338707120687 0.010167537454707887 0.9043427595181945" />
            </geometry>
        </collision>
    </link>
    <joint name="Torso05_Torso6" type="revolute">
       <parent link="Torso5"/>
       <child  link="Torso6"/>
       <origin rpy="0 0 0" xyz="0.7227338707120687 0 0" />
       <axis xyz="0 1 0"/>
       <limit effort="0.0" lower="-3.14159" upper="3.14159" velocity="0.0"/>
    </joint>
    <link name="Torso6">
        <inertial>
            <origin xyz="0.03074785022896953 0 0" rpy="0 0 0"/>
            <mass value="1" />
            <inertia ixx="100" ixy="0" ixz="0" iyy="100" iyz="0" izz="100" />
        </inertial>
        <visual>
            <origin xyz="0.03074785022896953 0 0" rpy="0 0 0"/>
            <geometry>
                <box size="0.06149570045793906 0.576801161696996 0.23502888462227656" />
            </geometry>
            <material name="Cyan">
                <color rgba="0 1.0 1.0 1.0"/>
            </material>
        </visual>
        <collision>
            <origin xyz="0.03074785022896953 0 0" rpy="0 0 0"/>
            <geometry>
                <box size="0.06149570045793906 0.576801161696996 0.23502888462227656" />
            </geometry>
        </collision>
    </link>
</robot>